{
 "cells": [
  {
   "cell_type": "markdown",
   "metadata": {},
   "source": [
    "# Выполнение домашнего задания к уроку номер № 8"
   ]
  },
  {
   "attachments": {},
   "cell_type": "markdown",
   "metadata": {},
   "source": [
    "1. Попробуйте улучшить работу нейронной сети рассмотренной в методическом пособии. Приложите анализ. Приложете лучшее сгенерированное изображение к уроку.\n",
    "2. Обратите внимание для запуска нейронной сети понадобиться tensorflow 2.1.0 и минимум 8gb опер. памяти(если запускать на процессоре)."
   ]
  },
  {
   "cell_type": "code",
   "execution_count": 1,
   "metadata": {},
   "outputs": [
    {
     "name": "stdout",
     "output_type": "stream",
     "text": [
      "Unexpected exception formatting exception. Falling back to standard exception\n"
     ]
    },
    {
     "name": "stderr",
     "output_type": "stream",
     "text": [
      "Traceback (most recent call last):\n",
      "  File \"c:\\Users\\azhur\\AppData\\Local\\Programs\\Python\\Python310\\lib\\site-packages\\IPython\\core\\interactiveshell.py\", line 3398, in run_code\n",
      "    exec(code_obj, self.user_global_ns, self.user_ns)\n",
      "  File \"C:\\Users\\azhur\\AppData\\Local\\Temp\\ipykernel_28916\\747801952.py\", line 1, in <cell line: 1>\n",
      "    import tensorflow as tf\n",
      "ModuleNotFoundError: No module named 'tensorflow'\n",
      "\n",
      "During handling of the above exception, another exception occurred:\n",
      "\n",
      "Traceback (most recent call last):\n",
      "  File \"c:\\Users\\azhur\\AppData\\Local\\Programs\\Python\\Python310\\lib\\site-packages\\IPython\\core\\interactiveshell.py\", line 1993, in showtraceback\n",
      "    stb = self.InteractiveTB.structured_traceback(\n",
      "  File \"c:\\Users\\azhur\\AppData\\Local\\Programs\\Python\\Python310\\lib\\site-packages\\IPython\\core\\ultratb.py\", line 1118, in structured_traceback\n",
      "    return FormattedTB.structured_traceback(\n",
      "  File \"c:\\Users\\azhur\\AppData\\Local\\Programs\\Python\\Python310\\lib\\site-packages\\IPython\\core\\ultratb.py\", line 1012, in structured_traceback\n",
      "    return VerboseTB.structured_traceback(\n",
      "  File \"c:\\Users\\azhur\\AppData\\Local\\Programs\\Python\\Python310\\lib\\site-packages\\IPython\\core\\ultratb.py\", line 865, in structured_traceback\n",
      "    formatted_exception = self.format_exception_as_a_whole(etype, evalue, etb, number_of_lines_of_context,\n",
      "  File \"c:\\Users\\azhur\\AppData\\Local\\Programs\\Python\\Python310\\lib\\site-packages\\IPython\\core\\ultratb.py\", line 799, in format_exception_as_a_whole\n",
      "    self.get_records(etb, number_of_lines_of_context, tb_offset) if etb else []\n",
      "  File \"c:\\Users\\azhur\\AppData\\Local\\Programs\\Python\\Python310\\lib\\site-packages\\IPython\\core\\ultratb.py\", line 845, in get_records\n",
      "    style = stack_data.style_with_executing_node(style, \"bg:ansiyellow\")\n",
      "  File \"c:\\Users\\azhur\\AppData\\Local\\Programs\\Python\\Python310\\lib\\site-packages\\stack_data\\core.py\", line 424, in style_with_executing_node\n",
      "    class NewStyle(style):\n",
      "  File \"c:\\Users\\azhur\\AppData\\Local\\Programs\\Python\\Python310\\lib\\site-packages\\pygments\\style.py\", line 91, in __new__\n",
      "    ndef[4] = colorformat(styledef[3:])\n",
      "  File \"c:\\Users\\azhur\\AppData\\Local\\Programs\\Python\\Python310\\lib\\site-packages\\pygments\\style.py\", line 58, in colorformat\n",
      "    assert False, \"wrong color format %r\" % text\n",
      "AssertionError: wrong color format 'ansiyellow'\n"
     ]
    }
   ],
   "source": [
    "import tensorflow as tf\n",
    "tf.config.experimental.set_visible_devices([], 'GPU')"
   ]
  },
  {
   "cell_type": "code",
   "execution_count": null,
   "metadata": {},
   "outputs": [],
   "source": [
    "import tensorflow_datasets as tfds\n",
    "from tensorflow_examples.models.pix2pix import pix2pix\n",
    "\n",
    "import os\n",
    "import time\n",
    "import matplotlib.pyplot as plt\n",
    "from IPython.display import clear_output\n",
    "\n",
    "tfds.disable_progress_bar()\n",
    "AUTOTUNE = tf.data.experimental.AUTOTUNE"
   ]
  },
  {
   "cell_type": "code",
   "execution_count": 3,
   "metadata": {},
   "outputs": [
    {
     "name": "stdout",
     "output_type": "stream",
     "text": [
      "Unexpected exception formatting exception. Falling back to standard exception\n"
     ]
    },
    {
     "name": "stderr",
     "output_type": "stream",
     "text": [
      "Traceback (most recent call last):\n",
      "  File \"c:\\Users\\azhur\\AppData\\Local\\Programs\\Python\\Python310\\lib\\site-packages\\IPython\\core\\interactiveshell.py\", line 3398, in run_code\n",
      "    exec(code_obj, self.user_global_ns, self.user_ns)\n",
      "  File \"C:\\Users\\azhur\\AppData\\Local\\Temp\\ipykernel_28916\\1879493382.py\", line 1, in <cell line: 1>\n",
      "    dataset, metadata = tfds.load('cycle_gan/horse2zebra',\n",
      "NameError: name 'tfds' is not defined\n",
      "\n",
      "During handling of the above exception, another exception occurred:\n",
      "\n",
      "Traceback (most recent call last):\n",
      "  File \"c:\\Users\\azhur\\AppData\\Local\\Programs\\Python\\Python310\\lib\\site-packages\\IPython\\core\\interactiveshell.py\", line 1993, in showtraceback\n",
      "    stb = self.InteractiveTB.structured_traceback(\n",
      "  File \"c:\\Users\\azhur\\AppData\\Local\\Programs\\Python\\Python310\\lib\\site-packages\\IPython\\core\\ultratb.py\", line 1118, in structured_traceback\n",
      "    return FormattedTB.structured_traceback(\n",
      "  File \"c:\\Users\\azhur\\AppData\\Local\\Programs\\Python\\Python310\\lib\\site-packages\\IPython\\core\\ultratb.py\", line 1012, in structured_traceback\n",
      "    return VerboseTB.structured_traceback(\n",
      "  File \"c:\\Users\\azhur\\AppData\\Local\\Programs\\Python\\Python310\\lib\\site-packages\\IPython\\core\\ultratb.py\", line 865, in structured_traceback\n",
      "    formatted_exception = self.format_exception_as_a_whole(etype, evalue, etb, number_of_lines_of_context,\n",
      "  File \"c:\\Users\\azhur\\AppData\\Local\\Programs\\Python\\Python310\\lib\\site-packages\\IPython\\core\\ultratb.py\", line 799, in format_exception_as_a_whole\n",
      "    self.get_records(etb, number_of_lines_of_context, tb_offset) if etb else []\n",
      "  File \"c:\\Users\\azhur\\AppData\\Local\\Programs\\Python\\Python310\\lib\\site-packages\\IPython\\core\\ultratb.py\", line 845, in get_records\n",
      "    style = stack_data.style_with_executing_node(style, \"bg:ansiyellow\")\n",
      "  File \"c:\\Users\\azhur\\AppData\\Local\\Programs\\Python\\Python310\\lib\\site-packages\\stack_data\\core.py\", line 424, in style_with_executing_node\n",
      "    class NewStyle(style):\n",
      "  File \"c:\\Users\\azhur\\AppData\\Local\\Programs\\Python\\Python310\\lib\\site-packages\\pygments\\style.py\", line 91, in __new__\n",
      "    ndef[4] = colorformat(styledef[3:])\n",
      "  File \"c:\\Users\\azhur\\AppData\\Local\\Programs\\Python\\Python310\\lib\\site-packages\\pygments\\style.py\", line 58, in colorformat\n",
      "    assert False, \"wrong color format %r\" % text\n",
      "AssertionError: wrong color format 'ansiyellow'\n"
     ]
    }
   ],
   "source": [
    "dataset, metadata = tfds.load('cycle_gan/horse2zebra',\n",
    "                              with_info=True, as_supervised=True)\n",
    "\n",
    "train_horses, train_zebras = dataset['trainA'], dataset['trainB']\n",
    "test_horses, test_zebras = dataset['testA'], dataset['testB']"
   ]
  },
  {
   "cell_type": "code",
   "execution_count": 4,
   "metadata": {},
   "outputs": [],
   "source": [
    "BUFFER_SIZE = 1000\n",
    "BATCH_SIZE = 1\n",
    "IMG_WIDTH = 256\n",
    "IMG_HEIGHT = 256"
   ]
  },
  {
   "cell_type": "code",
   "execution_count": 5,
   "metadata": {},
   "outputs": [],
   "source": [
    "def random_crop(image):\n",
    "  cropped_image = tf.image.random_crop(\n",
    "      image, size=[IMG_HEIGHT, IMG_WIDTH, 3])\n",
    "\n",
    "  return cropped_image"
   ]
  },
  {
   "cell_type": "code",
   "execution_count": 6,
   "metadata": {},
   "outputs": [],
   "source": [
    "# normalizing the images to [-1, 1]\n",
    "def normalize(image):\n",
    "  image = tf.cast(image, tf.float32)\n",
    "  image = (image / 127.5) - 1\n",
    "  return image"
   ]
  },
  {
   "cell_type": "code",
   "execution_count": 7,
   "metadata": {},
   "outputs": [],
   "source": [
    "def random_jitter(image):\n",
    "  # resizing to 286 x 286 x 3\n",
    "  image = tf.image.resize(image, [286, 286],\n",
    "                          method=tf.image.ResizeMethod.NEAREST_NEIGHBOR)\n",
    "\n",
    "  # randomly cropping to 256 x 256 x 3\n",
    "  image = random_crop(image)\n",
    "\n",
    "  # random mirroring\n",
    "  image = tf.image.random_flip_left_right(image)\n",
    "\n",
    "  return image"
   ]
  },
  {
   "cell_type": "code",
   "execution_count": 8,
   "metadata": {},
   "outputs": [],
   "source": [
    "def preprocess_image_train(image, label):\n",
    "  image = random_jitter(image)\n",
    "  image = normalize(image)\n",
    "  return image"
   ]
  },
  {
   "cell_type": "code",
   "execution_count": 9,
   "metadata": {},
   "outputs": [],
   "source": [
    "def preprocess_image_test(image, label):\n",
    "  image = normalize(image)\n",
    "  return image"
   ]
  },
  {
   "cell_type": "code",
   "execution_count": 10,
   "metadata": {},
   "outputs": [
    {
     "name": "stdout",
     "output_type": "stream",
     "text": [
      "Unexpected exception formatting exception. Falling back to standard exception\n"
     ]
    },
    {
     "name": "stderr",
     "output_type": "stream",
     "text": [
      "Traceback (most recent call last):\n",
      "  File \"c:\\Users\\azhur\\AppData\\Local\\Programs\\Python\\Python310\\lib\\site-packages\\IPython\\core\\interactiveshell.py\", line 3398, in run_code\n",
      "    exec(code_obj, self.user_global_ns, self.user_ns)\n",
      "  File \"C:\\Users\\azhur\\AppData\\Local\\Temp\\ipykernel_28916\\1086778511.py\", line 1, in <cell line: 1>\n",
      "    train_horses = train_horses.map(\n",
      "NameError: name 'train_horses' is not defined\n",
      "\n",
      "During handling of the above exception, another exception occurred:\n",
      "\n",
      "Traceback (most recent call last):\n",
      "  File \"c:\\Users\\azhur\\AppData\\Local\\Programs\\Python\\Python310\\lib\\site-packages\\IPython\\core\\interactiveshell.py\", line 1993, in showtraceback\n",
      "    stb = self.InteractiveTB.structured_traceback(\n",
      "  File \"c:\\Users\\azhur\\AppData\\Local\\Programs\\Python\\Python310\\lib\\site-packages\\IPython\\core\\ultratb.py\", line 1118, in structured_traceback\n",
      "    return FormattedTB.structured_traceback(\n",
      "  File \"c:\\Users\\azhur\\AppData\\Local\\Programs\\Python\\Python310\\lib\\site-packages\\IPython\\core\\ultratb.py\", line 1012, in structured_traceback\n",
      "    return VerboseTB.structured_traceback(\n",
      "  File \"c:\\Users\\azhur\\AppData\\Local\\Programs\\Python\\Python310\\lib\\site-packages\\IPython\\core\\ultratb.py\", line 865, in structured_traceback\n",
      "    formatted_exception = self.format_exception_as_a_whole(etype, evalue, etb, number_of_lines_of_context,\n",
      "  File \"c:\\Users\\azhur\\AppData\\Local\\Programs\\Python\\Python310\\lib\\site-packages\\IPython\\core\\ultratb.py\", line 799, in format_exception_as_a_whole\n",
      "    self.get_records(etb, number_of_lines_of_context, tb_offset) if etb else []\n",
      "  File \"c:\\Users\\azhur\\AppData\\Local\\Programs\\Python\\Python310\\lib\\site-packages\\IPython\\core\\ultratb.py\", line 845, in get_records\n",
      "    style = stack_data.style_with_executing_node(style, \"bg:ansiyellow\")\n",
      "  File \"c:\\Users\\azhur\\AppData\\Local\\Programs\\Python\\Python310\\lib\\site-packages\\stack_data\\core.py\", line 424, in style_with_executing_node\n",
      "    class NewStyle(style):\n",
      "  File \"c:\\Users\\azhur\\AppData\\Local\\Programs\\Python\\Python310\\lib\\site-packages\\pygments\\style.py\", line 91, in __new__\n",
      "    ndef[4] = colorformat(styledef[3:])\n",
      "  File \"c:\\Users\\azhur\\AppData\\Local\\Programs\\Python\\Python310\\lib\\site-packages\\pygments\\style.py\", line 58, in colorformat\n",
      "    assert False, \"wrong color format %r\" % text\n",
      "AssertionError: wrong color format 'ansiyellow'\n"
     ]
    }
   ],
   "source": [
    "train_horses = train_horses.map(\n",
    "    preprocess_image_train, num_parallel_calls=AUTOTUNE).cache().shuffle(\n",
    "    BUFFER_SIZE).batch(1)\n",
    "\n",
    "train_zebras = train_zebras.map(\n",
    "    preprocess_image_train, num_parallel_calls=AUTOTUNE).cache().shuffle(\n",
    "    BUFFER_SIZE).batch(1)\n",
    "\n",
    "test_horses = test_horses.map(\n",
    "    preprocess_image_test, num_parallel_calls=AUTOTUNE).cache().shuffle(\n",
    "    BUFFER_SIZE).batch(1)\n",
    "\n",
    "test_zebras = test_zebras.map(\n",
    "    preprocess_image_test, num_parallel_calls=AUTOTUNE).cache().shuffle(\n",
    "    BUFFER_SIZE).batch(1)"
   ]
  },
  {
   "cell_type": "code",
   "execution_count": 11,
   "metadata": {},
   "outputs": [
    {
     "name": "stdout",
     "output_type": "stream",
     "text": [
      "Unexpected exception formatting exception. Falling back to standard exception\n"
     ]
    },
    {
     "name": "stderr",
     "output_type": "stream",
     "text": [
      "Traceback (most recent call last):\n",
      "  File \"c:\\Users\\azhur\\AppData\\Local\\Programs\\Python\\Python310\\lib\\site-packages\\IPython\\core\\interactiveshell.py\", line 3398, in run_code\n",
      "    exec(code_obj, self.user_global_ns, self.user_ns)\n",
      "  File \"C:\\Users\\azhur\\AppData\\Local\\Temp\\ipykernel_28916\\3198301529.py\", line 1, in <cell line: 1>\n",
      "    sample_horse = next(iter(train_horses))\n",
      "NameError: name 'train_horses' is not defined\n",
      "\n",
      "During handling of the above exception, another exception occurred:\n",
      "\n",
      "Traceback (most recent call last):\n",
      "  File \"c:\\Users\\azhur\\AppData\\Local\\Programs\\Python\\Python310\\lib\\site-packages\\IPython\\core\\interactiveshell.py\", line 1993, in showtraceback\n",
      "    stb = self.InteractiveTB.structured_traceback(\n",
      "  File \"c:\\Users\\azhur\\AppData\\Local\\Programs\\Python\\Python310\\lib\\site-packages\\IPython\\core\\ultratb.py\", line 1118, in structured_traceback\n",
      "    return FormattedTB.structured_traceback(\n",
      "  File \"c:\\Users\\azhur\\AppData\\Local\\Programs\\Python\\Python310\\lib\\site-packages\\IPython\\core\\ultratb.py\", line 1012, in structured_traceback\n",
      "    return VerboseTB.structured_traceback(\n",
      "  File \"c:\\Users\\azhur\\AppData\\Local\\Programs\\Python\\Python310\\lib\\site-packages\\IPython\\core\\ultratb.py\", line 865, in structured_traceback\n",
      "    formatted_exception = self.format_exception_as_a_whole(etype, evalue, etb, number_of_lines_of_context,\n",
      "  File \"c:\\Users\\azhur\\AppData\\Local\\Programs\\Python\\Python310\\lib\\site-packages\\IPython\\core\\ultratb.py\", line 799, in format_exception_as_a_whole\n",
      "    self.get_records(etb, number_of_lines_of_context, tb_offset) if etb else []\n",
      "  File \"c:\\Users\\azhur\\AppData\\Local\\Programs\\Python\\Python310\\lib\\site-packages\\IPython\\core\\ultratb.py\", line 845, in get_records\n",
      "    style = stack_data.style_with_executing_node(style, \"bg:ansiyellow\")\n",
      "  File \"c:\\Users\\azhur\\AppData\\Local\\Programs\\Python\\Python310\\lib\\site-packages\\stack_data\\core.py\", line 424, in style_with_executing_node\n",
      "    class NewStyle(style):\n",
      "  File \"c:\\Users\\azhur\\AppData\\Local\\Programs\\Python\\Python310\\lib\\site-packages\\pygments\\style.py\", line 91, in __new__\n",
      "    ndef[4] = colorformat(styledef[3:])\n",
      "  File \"c:\\Users\\azhur\\AppData\\Local\\Programs\\Python\\Python310\\lib\\site-packages\\pygments\\style.py\", line 58, in colorformat\n",
      "    assert False, \"wrong color format %r\" % text\n",
      "AssertionError: wrong color format 'ansiyellow'\n"
     ]
    }
   ],
   "source": [
    "sample_horse = next(iter(train_horses))\n",
    "sample_zebra = next(iter(train_zebras))"
   ]
  },
  {
   "cell_type": "code",
   "execution_count": 12,
   "metadata": {},
   "outputs": [
    {
     "name": "stdout",
     "output_type": "stream",
     "text": [
      "Unexpected exception formatting exception. Falling back to standard exception\n"
     ]
    },
    {
     "name": "stderr",
     "output_type": "stream",
     "text": [
      "Traceback (most recent call last):\n",
      "  File \"c:\\Users\\azhur\\AppData\\Local\\Programs\\Python\\Python310\\lib\\site-packages\\IPython\\core\\interactiveshell.py\", line 3398, in run_code\n",
      "    exec(code_obj, self.user_global_ns, self.user_ns)\n",
      "  File \"C:\\Users\\azhur\\AppData\\Local\\Temp\\ipykernel_28916\\2533378719.py\", line 1, in <cell line: 1>\n",
      "    plt.subplot(121)\n",
      "NameError: name 'plt' is not defined\n",
      "\n",
      "During handling of the above exception, another exception occurred:\n",
      "\n",
      "Traceback (most recent call last):\n",
      "  File \"c:\\Users\\azhur\\AppData\\Local\\Programs\\Python\\Python310\\lib\\site-packages\\IPython\\core\\interactiveshell.py\", line 1993, in showtraceback\n",
      "    stb = self.InteractiveTB.structured_traceback(\n",
      "  File \"c:\\Users\\azhur\\AppData\\Local\\Programs\\Python\\Python310\\lib\\site-packages\\IPython\\core\\ultratb.py\", line 1118, in structured_traceback\n",
      "    return FormattedTB.structured_traceback(\n",
      "  File \"c:\\Users\\azhur\\AppData\\Local\\Programs\\Python\\Python310\\lib\\site-packages\\IPython\\core\\ultratb.py\", line 1012, in structured_traceback\n",
      "    return VerboseTB.structured_traceback(\n",
      "  File \"c:\\Users\\azhur\\AppData\\Local\\Programs\\Python\\Python310\\lib\\site-packages\\IPython\\core\\ultratb.py\", line 865, in structured_traceback\n",
      "    formatted_exception = self.format_exception_as_a_whole(etype, evalue, etb, number_of_lines_of_context,\n",
      "  File \"c:\\Users\\azhur\\AppData\\Local\\Programs\\Python\\Python310\\lib\\site-packages\\IPython\\core\\ultratb.py\", line 799, in format_exception_as_a_whole\n",
      "    self.get_records(etb, number_of_lines_of_context, tb_offset) if etb else []\n",
      "  File \"c:\\Users\\azhur\\AppData\\Local\\Programs\\Python\\Python310\\lib\\site-packages\\IPython\\core\\ultratb.py\", line 845, in get_records\n",
      "    style = stack_data.style_with_executing_node(style, \"bg:ansiyellow\")\n",
      "  File \"c:\\Users\\azhur\\AppData\\Local\\Programs\\Python\\Python310\\lib\\site-packages\\stack_data\\core.py\", line 424, in style_with_executing_node\n",
      "    class NewStyle(style):\n",
      "  File \"c:\\Users\\azhur\\AppData\\Local\\Programs\\Python\\Python310\\lib\\site-packages\\pygments\\style.py\", line 91, in __new__\n",
      "    ndef[4] = colorformat(styledef[3:])\n",
      "  File \"c:\\Users\\azhur\\AppData\\Local\\Programs\\Python\\Python310\\lib\\site-packages\\pygments\\style.py\", line 58, in colorformat\n",
      "    assert False, \"wrong color format %r\" % text\n",
      "AssertionError: wrong color format 'ansiyellow'\n"
     ]
    }
   ],
   "source": [
    "plt.subplot(121)\n",
    "plt.title('Horse')\n",
    "plt.imshow(sample_horse[0] * 0.5 + 0.5)\n",
    "\n",
    "plt.subplot(122)\n",
    "plt.title('Horse with random jitter')\n",
    "plt.imshow(random_jitter(sample_horse[0]) * 0.5 + 0.5)"
   ]
  },
  {
   "cell_type": "code",
   "execution_count": 13,
   "metadata": {},
   "outputs": [
    {
     "name": "stdout",
     "output_type": "stream",
     "text": [
      "Unexpected exception formatting exception. Falling back to standard exception\n"
     ]
    },
    {
     "name": "stderr",
     "output_type": "stream",
     "text": [
      "Traceback (most recent call last):\n",
      "  File \"c:\\Users\\azhur\\AppData\\Local\\Programs\\Python\\Python310\\lib\\site-packages\\IPython\\core\\interactiveshell.py\", line 3398, in run_code\n",
      "    exec(code_obj, self.user_global_ns, self.user_ns)\n",
      "  File \"C:\\Users\\azhur\\AppData\\Local\\Temp\\ipykernel_28916\\928267401.py\", line 1, in <cell line: 1>\n",
      "    plt.subplot(121)\n",
      "NameError: name 'plt' is not defined\n",
      "\n",
      "During handling of the above exception, another exception occurred:\n",
      "\n",
      "Traceback (most recent call last):\n",
      "  File \"c:\\Users\\azhur\\AppData\\Local\\Programs\\Python\\Python310\\lib\\site-packages\\IPython\\core\\interactiveshell.py\", line 1993, in showtraceback\n",
      "    stb = self.InteractiveTB.structured_traceback(\n",
      "  File \"c:\\Users\\azhur\\AppData\\Local\\Programs\\Python\\Python310\\lib\\site-packages\\IPython\\core\\ultratb.py\", line 1118, in structured_traceback\n",
      "    return FormattedTB.structured_traceback(\n",
      "  File \"c:\\Users\\azhur\\AppData\\Local\\Programs\\Python\\Python310\\lib\\site-packages\\IPython\\core\\ultratb.py\", line 1012, in structured_traceback\n",
      "    return VerboseTB.structured_traceback(\n",
      "  File \"c:\\Users\\azhur\\AppData\\Local\\Programs\\Python\\Python310\\lib\\site-packages\\IPython\\core\\ultratb.py\", line 865, in structured_traceback\n",
      "    formatted_exception = self.format_exception_as_a_whole(etype, evalue, etb, number_of_lines_of_context,\n",
      "  File \"c:\\Users\\azhur\\AppData\\Local\\Programs\\Python\\Python310\\lib\\site-packages\\IPython\\core\\ultratb.py\", line 799, in format_exception_as_a_whole\n",
      "    self.get_records(etb, number_of_lines_of_context, tb_offset) if etb else []\n",
      "  File \"c:\\Users\\azhur\\AppData\\Local\\Programs\\Python\\Python310\\lib\\site-packages\\IPython\\core\\ultratb.py\", line 845, in get_records\n",
      "    style = stack_data.style_with_executing_node(style, \"bg:ansiyellow\")\n",
      "  File \"c:\\Users\\azhur\\AppData\\Local\\Programs\\Python\\Python310\\lib\\site-packages\\stack_data\\core.py\", line 424, in style_with_executing_node\n",
      "    class NewStyle(style):\n",
      "  File \"c:\\Users\\azhur\\AppData\\Local\\Programs\\Python\\Python310\\lib\\site-packages\\pygments\\style.py\", line 91, in __new__\n",
      "    ndef[4] = colorformat(styledef[3:])\n",
      "  File \"c:\\Users\\azhur\\AppData\\Local\\Programs\\Python\\Python310\\lib\\site-packages\\pygments\\style.py\", line 58, in colorformat\n",
      "    assert False, \"wrong color format %r\" % text\n",
      "AssertionError: wrong color format 'ansiyellow'\n"
     ]
    }
   ],
   "source": [
    "plt.subplot(121)\n",
    "plt.title('Zebra')\n",
    "plt.imshow(sample_zebra[0] * 0.5 + 0.5)\n",
    "\n",
    "plt.subplot(122)\n",
    "plt.title('Zebra with random jitter')\n",
    "plt.imshow(random_jitter(sample_zebra[0]) * 0.5 + 0.5)"
   ]
  },
  {
   "cell_type": "code",
   "execution_count": 14,
   "metadata": {},
   "outputs": [
    {
     "name": "stdout",
     "output_type": "stream",
     "text": [
      "Unexpected exception formatting exception. Falling back to standard exception\n"
     ]
    },
    {
     "name": "stderr",
     "output_type": "stream",
     "text": [
      "Traceback (most recent call last):\n",
      "  File \"c:\\Users\\azhur\\AppData\\Local\\Programs\\Python\\Python310\\lib\\site-packages\\IPython\\core\\interactiveshell.py\", line 3398, in run_code\n",
      "    exec(code_obj, self.user_global_ns, self.user_ns)\n",
      "  File \"C:\\Users\\azhur\\AppData\\Local\\Temp\\ipykernel_28916\\958529822.py\", line 3, in <cell line: 3>\n",
      "    generator_g = pix2pix.unet_generator(OUTPUT_CHANNELS, norm_type='instancenorm')\n",
      "NameError: name 'pix2pix' is not defined\n",
      "\n",
      "During handling of the above exception, another exception occurred:\n",
      "\n",
      "Traceback (most recent call last):\n",
      "  File \"c:\\Users\\azhur\\AppData\\Local\\Programs\\Python\\Python310\\lib\\site-packages\\IPython\\core\\interactiveshell.py\", line 1993, in showtraceback\n",
      "    stb = self.InteractiveTB.structured_traceback(\n",
      "  File \"c:\\Users\\azhur\\AppData\\Local\\Programs\\Python\\Python310\\lib\\site-packages\\IPython\\core\\ultratb.py\", line 1118, in structured_traceback\n",
      "    return FormattedTB.structured_traceback(\n",
      "  File \"c:\\Users\\azhur\\AppData\\Local\\Programs\\Python\\Python310\\lib\\site-packages\\IPython\\core\\ultratb.py\", line 1012, in structured_traceback\n",
      "    return VerboseTB.structured_traceback(\n",
      "  File \"c:\\Users\\azhur\\AppData\\Local\\Programs\\Python\\Python310\\lib\\site-packages\\IPython\\core\\ultratb.py\", line 865, in structured_traceback\n",
      "    formatted_exception = self.format_exception_as_a_whole(etype, evalue, etb, number_of_lines_of_context,\n",
      "  File \"c:\\Users\\azhur\\AppData\\Local\\Programs\\Python\\Python310\\lib\\site-packages\\IPython\\core\\ultratb.py\", line 799, in format_exception_as_a_whole\n",
      "    self.get_records(etb, number_of_lines_of_context, tb_offset) if etb else []\n",
      "  File \"c:\\Users\\azhur\\AppData\\Local\\Programs\\Python\\Python310\\lib\\site-packages\\IPython\\core\\ultratb.py\", line 845, in get_records\n",
      "    style = stack_data.style_with_executing_node(style, \"bg:ansiyellow\")\n",
      "  File \"c:\\Users\\azhur\\AppData\\Local\\Programs\\Python\\Python310\\lib\\site-packages\\stack_data\\core.py\", line 424, in style_with_executing_node\n",
      "    class NewStyle(style):\n",
      "  File \"c:\\Users\\azhur\\AppData\\Local\\Programs\\Python\\Python310\\lib\\site-packages\\pygments\\style.py\", line 91, in __new__\n",
      "    ndef[4] = colorformat(styledef[3:])\n",
      "  File \"c:\\Users\\azhur\\AppData\\Local\\Programs\\Python\\Python310\\lib\\site-packages\\pygments\\style.py\", line 58, in colorformat\n",
      "    assert False, \"wrong color format %r\" % text\n",
      "AssertionError: wrong color format 'ansiyellow'\n"
     ]
    }
   ],
   "source": [
    "OUTPUT_CHANNELS = 3\n",
    "\n",
    "generator_g = pix2pix.unet_generator(OUTPUT_CHANNELS, norm_type='instancenorm')\n",
    "generator_f = pix2pix.unet_generator(OUTPUT_CHANNELS, norm_type='instancenorm')\n",
    "\n",
    "discriminator_x = pix2pix.discriminator(norm_type='instancenorm', target=False)\n",
    "discriminator_y = pix2pix.discriminator(norm_type='instancenorm', target=False)"
   ]
  },
  {
   "cell_type": "code",
   "execution_count": 15,
   "metadata": {},
   "outputs": [
    {
     "name": "stdout",
     "output_type": "stream",
     "text": [
      "Unexpected exception formatting exception. Falling back to standard exception\n"
     ]
    },
    {
     "name": "stderr",
     "output_type": "stream",
     "text": [
      "Traceback (most recent call last):\n",
      "  File \"c:\\Users\\azhur\\AppData\\Local\\Programs\\Python\\Python310\\lib\\site-packages\\IPython\\core\\interactiveshell.py\", line 3398, in run_code\n",
      "    exec(code_obj, self.user_global_ns, self.user_ns)\n",
      "  File \"C:\\Users\\azhur\\AppData\\Local\\Temp\\ipykernel_28916\\1907201739.py\", line 1, in <cell line: 1>\n",
      "    to_zebra = generator_g(sample_horse)\n",
      "NameError: name 'generator_g' is not defined\n",
      "\n",
      "During handling of the above exception, another exception occurred:\n",
      "\n",
      "Traceback (most recent call last):\n",
      "  File \"c:\\Users\\azhur\\AppData\\Local\\Programs\\Python\\Python310\\lib\\site-packages\\IPython\\core\\interactiveshell.py\", line 1993, in showtraceback\n",
      "    stb = self.InteractiveTB.structured_traceback(\n",
      "  File \"c:\\Users\\azhur\\AppData\\Local\\Programs\\Python\\Python310\\lib\\site-packages\\IPython\\core\\ultratb.py\", line 1118, in structured_traceback\n",
      "    return FormattedTB.structured_traceback(\n",
      "  File \"c:\\Users\\azhur\\AppData\\Local\\Programs\\Python\\Python310\\lib\\site-packages\\IPython\\core\\ultratb.py\", line 1012, in structured_traceback\n",
      "    return VerboseTB.structured_traceback(\n",
      "  File \"c:\\Users\\azhur\\AppData\\Local\\Programs\\Python\\Python310\\lib\\site-packages\\IPython\\core\\ultratb.py\", line 865, in structured_traceback\n",
      "    formatted_exception = self.format_exception_as_a_whole(etype, evalue, etb, number_of_lines_of_context,\n",
      "  File \"c:\\Users\\azhur\\AppData\\Local\\Programs\\Python\\Python310\\lib\\site-packages\\IPython\\core\\ultratb.py\", line 799, in format_exception_as_a_whole\n",
      "    self.get_records(etb, number_of_lines_of_context, tb_offset) if etb else []\n",
      "  File \"c:\\Users\\azhur\\AppData\\Local\\Programs\\Python\\Python310\\lib\\site-packages\\IPython\\core\\ultratb.py\", line 845, in get_records\n",
      "    style = stack_data.style_with_executing_node(style, \"bg:ansiyellow\")\n",
      "  File \"c:\\Users\\azhur\\AppData\\Local\\Programs\\Python\\Python310\\lib\\site-packages\\stack_data\\core.py\", line 424, in style_with_executing_node\n",
      "    class NewStyle(style):\n",
      "  File \"c:\\Users\\azhur\\AppData\\Local\\Programs\\Python\\Python310\\lib\\site-packages\\pygments\\style.py\", line 91, in __new__\n",
      "    ndef[4] = colorformat(styledef[3:])\n",
      "  File \"c:\\Users\\azhur\\AppData\\Local\\Programs\\Python\\Python310\\lib\\site-packages\\pygments\\style.py\", line 58, in colorformat\n",
      "    assert False, \"wrong color format %r\" % text\n",
      "AssertionError: wrong color format 'ansiyellow'\n"
     ]
    }
   ],
   "source": [
    "to_zebra = generator_g(sample_horse)\n",
    "to_horse = generator_f(sample_zebra)\n",
    "plt.figure(figsize=(8, 8))\n",
    "contrast = 8\n",
    "\n",
    "imgs = [sample_horse, to_zebra, sample_zebra, to_horse]\n",
    "title = ['Horse', 'To Zebra', 'Zebra', 'To Horse']\n",
    "\n",
    "for i in range(len(imgs)):\n",
    "  plt.subplot(2, 2, i+1)\n",
    "  plt.title(title[i])\n",
    "  if i % 2 == 0:\n",
    "    plt.imshow(imgs[i][0] * 0.5 + 0.5)\n",
    "  else:\n",
    "    plt.imshow(imgs[i][0] * 0.5 * contrast + 0.5)\n",
    "plt.show()"
   ]
  },
  {
   "cell_type": "code",
   "execution_count": 16,
   "metadata": {},
   "outputs": [
    {
     "name": "stdout",
     "output_type": "stream",
     "text": [
      "Unexpected exception formatting exception. Falling back to standard exception\n"
     ]
    },
    {
     "name": "stderr",
     "output_type": "stream",
     "text": [
      "Traceback (most recent call last):\n",
      "  File \"c:\\Users\\azhur\\AppData\\Local\\Programs\\Python\\Python310\\lib\\site-packages\\IPython\\core\\interactiveshell.py\", line 3398, in run_code\n",
      "    exec(code_obj, self.user_global_ns, self.user_ns)\n",
      "  File \"C:\\Users\\azhur\\AppData\\Local\\Temp\\ipykernel_28916\\352635955.py\", line 1, in <cell line: 1>\n",
      "    plt.figure(figsize=(8, 8))\n",
      "NameError: name 'plt' is not defined\n",
      "\n",
      "During handling of the above exception, another exception occurred:\n",
      "\n",
      "Traceback (most recent call last):\n",
      "  File \"c:\\Users\\azhur\\AppData\\Local\\Programs\\Python\\Python310\\lib\\site-packages\\IPython\\core\\interactiveshell.py\", line 1993, in showtraceback\n",
      "    stb = self.InteractiveTB.structured_traceback(\n",
      "  File \"c:\\Users\\azhur\\AppData\\Local\\Programs\\Python\\Python310\\lib\\site-packages\\IPython\\core\\ultratb.py\", line 1118, in structured_traceback\n",
      "    return FormattedTB.structured_traceback(\n",
      "  File \"c:\\Users\\azhur\\AppData\\Local\\Programs\\Python\\Python310\\lib\\site-packages\\IPython\\core\\ultratb.py\", line 1012, in structured_traceback\n",
      "    return VerboseTB.structured_traceback(\n",
      "  File \"c:\\Users\\azhur\\AppData\\Local\\Programs\\Python\\Python310\\lib\\site-packages\\IPython\\core\\ultratb.py\", line 865, in structured_traceback\n",
      "    formatted_exception = self.format_exception_as_a_whole(etype, evalue, etb, number_of_lines_of_context,\n",
      "  File \"c:\\Users\\azhur\\AppData\\Local\\Programs\\Python\\Python310\\lib\\site-packages\\IPython\\core\\ultratb.py\", line 799, in format_exception_as_a_whole\n",
      "    self.get_records(etb, number_of_lines_of_context, tb_offset) if etb else []\n",
      "  File \"c:\\Users\\azhur\\AppData\\Local\\Programs\\Python\\Python310\\lib\\site-packages\\IPython\\core\\ultratb.py\", line 845, in get_records\n",
      "    style = stack_data.style_with_executing_node(style, \"bg:ansiyellow\")\n",
      "  File \"c:\\Users\\azhur\\AppData\\Local\\Programs\\Python\\Python310\\lib\\site-packages\\stack_data\\core.py\", line 424, in style_with_executing_node\n",
      "    class NewStyle(style):\n",
      "  File \"c:\\Users\\azhur\\AppData\\Local\\Programs\\Python\\Python310\\lib\\site-packages\\pygments\\style.py\", line 91, in __new__\n",
      "    ndef[4] = colorformat(styledef[3:])\n",
      "  File \"c:\\Users\\azhur\\AppData\\Local\\Programs\\Python\\Python310\\lib\\site-packages\\pygments\\style.py\", line 58, in colorformat\n",
      "    assert False, \"wrong color format %r\" % text\n",
      "AssertionError: wrong color format 'ansiyellow'\n"
     ]
    }
   ],
   "source": [
    "plt.figure(figsize=(8, 8))\n",
    "\n",
    "plt.subplot(121)\n",
    "plt.title('Is a real zebra?')\n",
    "plt.imshow(discriminator_y(sample_zebra)[0, ..., -1], cmap='RdBu_r')\n",
    "\n",
    "plt.subplot(122)\n",
    "plt.title('Is a real horse?')\n",
    "plt.imshow(discriminator_x(sample_horse)[0, ..., -1], cmap='RdBu_r')\n",
    "\n",
    "plt.show()\n"
   ]
  },
  {
   "cell_type": "code",
   "execution_count": 17,
   "metadata": {},
   "outputs": [],
   "source": [
    "LAMBDA = 10"
   ]
  },
  {
   "cell_type": "code",
   "execution_count": 18,
   "metadata": {},
   "outputs": [
    {
     "name": "stdout",
     "output_type": "stream",
     "text": [
      "Unexpected exception formatting exception. Falling back to standard exception\n"
     ]
    },
    {
     "name": "stderr",
     "output_type": "stream",
     "text": [
      "Traceback (most recent call last):\n",
      "  File \"c:\\Users\\azhur\\AppData\\Local\\Programs\\Python\\Python310\\lib\\site-packages\\IPython\\core\\interactiveshell.py\", line 3398, in run_code\n",
      "    exec(code_obj, self.user_global_ns, self.user_ns)\n",
      "  File \"C:\\Users\\azhur\\AppData\\Local\\Temp\\ipykernel_28916\\300559631.py\", line 1, in <cell line: 1>\n",
      "    loss_obj = tf.keras.losses.BinaryCrossentropy(from_logits=True)\n",
      "NameError: name 'tf' is not defined\n",
      "\n",
      "During handling of the above exception, another exception occurred:\n",
      "\n",
      "Traceback (most recent call last):\n",
      "  File \"c:\\Users\\azhur\\AppData\\Local\\Programs\\Python\\Python310\\lib\\site-packages\\IPython\\core\\interactiveshell.py\", line 1993, in showtraceback\n",
      "    stb = self.InteractiveTB.structured_traceback(\n",
      "  File \"c:\\Users\\azhur\\AppData\\Local\\Programs\\Python\\Python310\\lib\\site-packages\\IPython\\core\\ultratb.py\", line 1118, in structured_traceback\n",
      "    return FormattedTB.structured_traceback(\n",
      "  File \"c:\\Users\\azhur\\AppData\\Local\\Programs\\Python\\Python310\\lib\\site-packages\\IPython\\core\\ultratb.py\", line 1012, in structured_traceback\n",
      "    return VerboseTB.structured_traceback(\n",
      "  File \"c:\\Users\\azhur\\AppData\\Local\\Programs\\Python\\Python310\\lib\\site-packages\\IPython\\core\\ultratb.py\", line 865, in structured_traceback\n",
      "    formatted_exception = self.format_exception_as_a_whole(etype, evalue, etb, number_of_lines_of_context,\n",
      "  File \"c:\\Users\\azhur\\AppData\\Local\\Programs\\Python\\Python310\\lib\\site-packages\\IPython\\core\\ultratb.py\", line 799, in format_exception_as_a_whole\n",
      "    self.get_records(etb, number_of_lines_of_context, tb_offset) if etb else []\n",
      "  File \"c:\\Users\\azhur\\AppData\\Local\\Programs\\Python\\Python310\\lib\\site-packages\\IPython\\core\\ultratb.py\", line 845, in get_records\n",
      "    style = stack_data.style_with_executing_node(style, \"bg:ansiyellow\")\n",
      "  File \"c:\\Users\\azhur\\AppData\\Local\\Programs\\Python\\Python310\\lib\\site-packages\\stack_data\\core.py\", line 424, in style_with_executing_node\n",
      "    class NewStyle(style):\n",
      "  File \"c:\\Users\\azhur\\AppData\\Local\\Programs\\Python\\Python310\\lib\\site-packages\\pygments\\style.py\", line 91, in __new__\n",
      "    ndef[4] = colorformat(styledef[3:])\n",
      "  File \"c:\\Users\\azhur\\AppData\\Local\\Programs\\Python\\Python310\\lib\\site-packages\\pygments\\style.py\", line 58, in colorformat\n",
      "    assert False, \"wrong color format %r\" % text\n",
      "AssertionError: wrong color format 'ansiyellow'\n"
     ]
    }
   ],
   "source": [
    "loss_obj = tf.keras.losses.BinaryCrossentropy(from_logits=True)"
   ]
  },
  {
   "cell_type": "code",
   "execution_count": 19,
   "metadata": {},
   "outputs": [],
   "source": [
    "def discriminator_loss(real, generated):\n",
    "  real_loss = loss_obj(tf.ones_like(real), real)\n",
    "\n",
    "  generated_loss = loss_obj(tf.zeros_like(generated), generated)\n",
    "\n",
    "  total_disc_loss = real_loss + generated_loss\n",
    "\n",
    "  return total_disc_loss * 0.5"
   ]
  },
  {
   "cell_type": "code",
   "execution_count": 20,
   "metadata": {},
   "outputs": [],
   "source": [
    "def generator_loss(generated):\n",
    "  return loss_obj(tf.ones_like(generated), generated)"
   ]
  },
  {
   "cell_type": "code",
   "execution_count": 21,
   "metadata": {},
   "outputs": [],
   "source": [
    "def calc_cycle_loss(real_image, cycled_image):\n",
    "  loss1 = tf.reduce_mean(tf.abs(real_image - cycled_image))\n",
    "  \n",
    "  return LAMBDA * loss1"
   ]
  },
  {
   "cell_type": "code",
   "execution_count": 22,
   "metadata": {},
   "outputs": [],
   "source": [
    "def identity_loss(real_image, same_image):\n",
    "  loss = tf.reduce_mean(tf.abs(real_image - same_image))\n",
    "  return LAMBDA * 0.5 * loss"
   ]
  },
  {
   "cell_type": "code",
   "execution_count": 23,
   "metadata": {},
   "outputs": [
    {
     "name": "stdout",
     "output_type": "stream",
     "text": [
      "Unexpected exception formatting exception. Falling back to standard exception\n"
     ]
    },
    {
     "name": "stderr",
     "output_type": "stream",
     "text": [
      "Traceback (most recent call last):\n",
      "  File \"c:\\Users\\azhur\\AppData\\Local\\Programs\\Python\\Python310\\lib\\site-packages\\IPython\\core\\interactiveshell.py\", line 3398, in run_code\n",
      "    exec(code_obj, self.user_global_ns, self.user_ns)\n",
      "  File \"C:\\Users\\azhur\\AppData\\Local\\Temp\\ipykernel_28916\\2537496680.py\", line 1, in <cell line: 1>\n",
      "    generator_g_optimizer = tf.keras.optimizers.Adam(2e-4, beta_1=0.5)\n",
      "NameError: name 'tf' is not defined\n",
      "\n",
      "During handling of the above exception, another exception occurred:\n",
      "\n",
      "Traceback (most recent call last):\n",
      "  File \"c:\\Users\\azhur\\AppData\\Local\\Programs\\Python\\Python310\\lib\\site-packages\\IPython\\core\\interactiveshell.py\", line 1993, in showtraceback\n",
      "    stb = self.InteractiveTB.structured_traceback(\n",
      "  File \"c:\\Users\\azhur\\AppData\\Local\\Programs\\Python\\Python310\\lib\\site-packages\\IPython\\core\\ultratb.py\", line 1118, in structured_traceback\n",
      "    return FormattedTB.structured_traceback(\n",
      "  File \"c:\\Users\\azhur\\AppData\\Local\\Programs\\Python\\Python310\\lib\\site-packages\\IPython\\core\\ultratb.py\", line 1012, in structured_traceback\n",
      "    return VerboseTB.structured_traceback(\n",
      "  File \"c:\\Users\\azhur\\AppData\\Local\\Programs\\Python\\Python310\\lib\\site-packages\\IPython\\core\\ultratb.py\", line 865, in structured_traceback\n",
      "    formatted_exception = self.format_exception_as_a_whole(etype, evalue, etb, number_of_lines_of_context,\n",
      "  File \"c:\\Users\\azhur\\AppData\\Local\\Programs\\Python\\Python310\\lib\\site-packages\\IPython\\core\\ultratb.py\", line 799, in format_exception_as_a_whole\n",
      "    self.get_records(etb, number_of_lines_of_context, tb_offset) if etb else []\n",
      "  File \"c:\\Users\\azhur\\AppData\\Local\\Programs\\Python\\Python310\\lib\\site-packages\\IPython\\core\\ultratb.py\", line 845, in get_records\n",
      "    style = stack_data.style_with_executing_node(style, \"bg:ansiyellow\")\n",
      "  File \"c:\\Users\\azhur\\AppData\\Local\\Programs\\Python\\Python310\\lib\\site-packages\\stack_data\\core.py\", line 424, in style_with_executing_node\n",
      "    class NewStyle(style):\n",
      "  File \"c:\\Users\\azhur\\AppData\\Local\\Programs\\Python\\Python310\\lib\\site-packages\\pygments\\style.py\", line 91, in __new__\n",
      "    ndef[4] = colorformat(styledef[3:])\n",
      "  File \"c:\\Users\\azhur\\AppData\\Local\\Programs\\Python\\Python310\\lib\\site-packages\\pygments\\style.py\", line 58, in colorformat\n",
      "    assert False, \"wrong color format %r\" % text\n",
      "AssertionError: wrong color format 'ansiyellow'\n"
     ]
    }
   ],
   "source": [
    "generator_g_optimizer = tf.keras.optimizers.Adam(2e-4, beta_1=0.5)\n",
    "generator_f_optimizer = tf.keras.optimizers.Adam(2e-4, beta_1=0.5)\n",
    "\n",
    "discriminator_x_optimizer = tf.keras.optimizers.Adam(2e-4, beta_1=0.5)\n",
    "discriminator_y_optimizer = tf.keras.optimizers.Adam(2e-4, beta_1=0.5)"
   ]
  },
  {
   "cell_type": "code",
   "execution_count": 24,
   "metadata": {},
   "outputs": [
    {
     "name": "stdout",
     "output_type": "stream",
     "text": [
      "Unexpected exception formatting exception. Falling back to standard exception\n"
     ]
    },
    {
     "name": "stderr",
     "output_type": "stream",
     "text": [
      "Traceback (most recent call last):\n",
      "  File \"c:\\Users\\azhur\\AppData\\Local\\Programs\\Python\\Python310\\lib\\site-packages\\IPython\\core\\interactiveshell.py\", line 3398, in run_code\n",
      "    exec(code_obj, self.user_global_ns, self.user_ns)\n",
      "  File \"C:\\Users\\azhur\\AppData\\Local\\Temp\\ipykernel_28916\\1274904833.py\", line 3, in <cell line: 3>\n",
      "    ckpt = tf.train.Checkpoint(generator_g=generator_g,\n",
      "NameError: name 'tf' is not defined\n",
      "\n",
      "During handling of the above exception, another exception occurred:\n",
      "\n",
      "Traceback (most recent call last):\n",
      "  File \"c:\\Users\\azhur\\AppData\\Local\\Programs\\Python\\Python310\\lib\\site-packages\\IPython\\core\\interactiveshell.py\", line 1993, in showtraceback\n",
      "    stb = self.InteractiveTB.structured_traceback(\n",
      "  File \"c:\\Users\\azhur\\AppData\\Local\\Programs\\Python\\Python310\\lib\\site-packages\\IPython\\core\\ultratb.py\", line 1118, in structured_traceback\n",
      "    return FormattedTB.structured_traceback(\n",
      "  File \"c:\\Users\\azhur\\AppData\\Local\\Programs\\Python\\Python310\\lib\\site-packages\\IPython\\core\\ultratb.py\", line 1012, in structured_traceback\n",
      "    return VerboseTB.structured_traceback(\n",
      "  File \"c:\\Users\\azhur\\AppData\\Local\\Programs\\Python\\Python310\\lib\\site-packages\\IPython\\core\\ultratb.py\", line 865, in structured_traceback\n",
      "    formatted_exception = self.format_exception_as_a_whole(etype, evalue, etb, number_of_lines_of_context,\n",
      "  File \"c:\\Users\\azhur\\AppData\\Local\\Programs\\Python\\Python310\\lib\\site-packages\\IPython\\core\\ultratb.py\", line 799, in format_exception_as_a_whole\n",
      "    self.get_records(etb, number_of_lines_of_context, tb_offset) if etb else []\n",
      "  File \"c:\\Users\\azhur\\AppData\\Local\\Programs\\Python\\Python310\\lib\\site-packages\\IPython\\core\\ultratb.py\", line 845, in get_records\n",
      "    style = stack_data.style_with_executing_node(style, \"bg:ansiyellow\")\n",
      "  File \"c:\\Users\\azhur\\AppData\\Local\\Programs\\Python\\Python310\\lib\\site-packages\\stack_data\\core.py\", line 424, in style_with_executing_node\n",
      "    class NewStyle(style):\n",
      "  File \"c:\\Users\\azhur\\AppData\\Local\\Programs\\Python\\Python310\\lib\\site-packages\\pygments\\style.py\", line 91, in __new__\n",
      "    ndef[4] = colorformat(styledef[3:])\n",
      "  File \"c:\\Users\\azhur\\AppData\\Local\\Programs\\Python\\Python310\\lib\\site-packages\\pygments\\style.py\", line 58, in colorformat\n",
      "    assert False, \"wrong color format %r\" % text\n",
      "AssertionError: wrong color format 'ansiyellow'\n"
     ]
    }
   ],
   "source": [
    "checkpoint_path = \"./checkpoints/train\"\n",
    "\n",
    "ckpt = tf.train.Checkpoint(generator_g=generator_g,\n",
    "                           generator_f=generator_f,\n",
    "                           discriminator_x=discriminator_x,\n",
    "                           discriminator_y=discriminator_y,\n",
    "                           generator_g_optimizer=generator_g_optimizer,\n",
    "                           generator_f_optimizer=generator_f_optimizer,\n",
    "                           discriminator_x_optimizer=discriminator_x_optimizer,\n",
    "                           discriminator_y_optimizer=discriminator_y_optimizer)\n",
    "\n",
    "ckpt_manager = tf.train.CheckpointManager(ckpt, checkpoint_path, max_to_keep=5)\n",
    "\n",
    "# if a checkpoint exists, restore the latest checkpoint.\n",
    "if ckpt_manager.latest_checkpoint:\n",
    "  ckpt.restore(ckpt_manager.latest_checkpoint)\n",
    "  print ('Latest checkpoint restored!!')"
   ]
  },
  {
   "cell_type": "code",
   "execution_count": 25,
   "metadata": {},
   "outputs": [],
   "source": [
    "EPOCHS = 1"
   ]
  },
  {
   "cell_type": "code",
   "execution_count": 26,
   "metadata": {},
   "outputs": [],
   "source": [
    "def generate_images(model, test_input):\n",
    "  prediction = model(test_input)\n",
    "    \n",
    "  plt.figure(figsize=(12, 12))\n",
    "\n",
    "  display_list = [test_input[0], prediction[0]]\n",
    "  title = ['Input Image', 'Predicted Image']\n",
    "\n",
    "  for i in range(2):\n",
    "    plt.subplot(1, 2, i+1)\n",
    "    plt.title(title[i])\n",
    "    # getting the pixel values between [0, 1] to plot it.\n",
    "    plt.imshow(display_list[i] * 0.5 + 0.5)\n",
    "    plt.axis('off')\n",
    "  plt.show()"
   ]
  },
  {
   "cell_type": "code",
   "execution_count": 27,
   "metadata": {},
   "outputs": [
    {
     "name": "stdout",
     "output_type": "stream",
     "text": [
      "Unexpected exception formatting exception. Falling back to standard exception\n"
     ]
    },
    {
     "name": "stderr",
     "output_type": "stream",
     "text": [
      "Traceback (most recent call last):\n",
      "  File \"c:\\Users\\azhur\\AppData\\Local\\Programs\\Python\\Python310\\lib\\site-packages\\IPython\\core\\interactiveshell.py\", line 3398, in run_code\n",
      "    exec(code_obj, self.user_global_ns, self.user_ns)\n",
      "  File \"C:\\Users\\azhur\\AppData\\Local\\Temp\\ipykernel_28916\\2562194491.py\", line 1, in <cell line: 1>\n",
      "    @tf.function\n",
      "NameError: name 'tf' is not defined\n",
      "\n",
      "During handling of the above exception, another exception occurred:\n",
      "\n",
      "Traceback (most recent call last):\n",
      "  File \"c:\\Users\\azhur\\AppData\\Local\\Programs\\Python\\Python310\\lib\\site-packages\\IPython\\core\\interactiveshell.py\", line 1993, in showtraceback\n",
      "    stb = self.InteractiveTB.structured_traceback(\n",
      "  File \"c:\\Users\\azhur\\AppData\\Local\\Programs\\Python\\Python310\\lib\\site-packages\\IPython\\core\\ultratb.py\", line 1118, in structured_traceback\n",
      "    return FormattedTB.structured_traceback(\n",
      "  File \"c:\\Users\\azhur\\AppData\\Local\\Programs\\Python\\Python310\\lib\\site-packages\\IPython\\core\\ultratb.py\", line 1012, in structured_traceback\n",
      "    return VerboseTB.structured_traceback(\n",
      "  File \"c:\\Users\\azhur\\AppData\\Local\\Programs\\Python\\Python310\\lib\\site-packages\\IPython\\core\\ultratb.py\", line 865, in structured_traceback\n",
      "    formatted_exception = self.format_exception_as_a_whole(etype, evalue, etb, number_of_lines_of_context,\n",
      "  File \"c:\\Users\\azhur\\AppData\\Local\\Programs\\Python\\Python310\\lib\\site-packages\\IPython\\core\\ultratb.py\", line 799, in format_exception_as_a_whole\n",
      "    self.get_records(etb, number_of_lines_of_context, tb_offset) if etb else []\n",
      "  File \"c:\\Users\\azhur\\AppData\\Local\\Programs\\Python\\Python310\\lib\\site-packages\\IPython\\core\\ultratb.py\", line 845, in get_records\n",
      "    style = stack_data.style_with_executing_node(style, \"bg:ansiyellow\")\n",
      "  File \"c:\\Users\\azhur\\AppData\\Local\\Programs\\Python\\Python310\\lib\\site-packages\\stack_data\\core.py\", line 424, in style_with_executing_node\n",
      "    class NewStyle(style):\n",
      "  File \"c:\\Users\\azhur\\AppData\\Local\\Programs\\Python\\Python310\\lib\\site-packages\\pygments\\style.py\", line 91, in __new__\n",
      "    ndef[4] = colorformat(styledef[3:])\n",
      "  File \"c:\\Users\\azhur\\AppData\\Local\\Programs\\Python\\Python310\\lib\\site-packages\\pygments\\style.py\", line 58, in colorformat\n",
      "    assert False, \"wrong color format %r\" % text\n",
      "AssertionError: wrong color format 'ansiyellow'\n"
     ]
    }
   ],
   "source": [
    "@tf.function\n",
    "def train_step(real_x, real_y):\n",
    "  # persistent is set to True because the tape is used more than\n",
    "  # once to calculate the gradients.\n",
    "  with tf.GradientTape(persistent=True) as tape:\n",
    "    # Generator G translates X -> Y\n",
    "    # Generator F translates Y -> X.\n",
    "    \n",
    "    fake_y = generator_g(real_x, training=True)\n",
    "    cycled_x = generator_f(fake_y, training=True)\n",
    "\n",
    "    fake_x = generator_f(real_y, training=True)\n",
    "    cycled_y = generator_g(fake_x, training=True)\n",
    "\n",
    "    # same_x and same_y are used for identity loss.\n",
    "    same_x = generator_f(real_x, training=True)\n",
    "    same_y = generator_g(real_y, training=True)\n",
    "\n",
    "    disc_real_x = discriminator_x(real_x, training=True)\n",
    "    disc_real_y = discriminator_y(real_y, training=True)\n",
    "\n",
    "    disc_fake_x = discriminator_x(fake_x, training=True)\n",
    "    disc_fake_y = discriminator_y(fake_y, training=True)\n",
    "\n",
    "    # calculate the loss\n",
    "    gen_g_loss = generator_loss(disc_fake_y)\n",
    "    gen_f_loss = generator_loss(disc_fake_x)\n",
    "    \n",
    "    total_cycle_loss = calc_cycle_loss(real_x, cycled_x) + calc_cycle_loss(real_y, cycled_y)\n",
    "    \n",
    "    # Total generator loss = adversarial loss + cycle loss\n",
    "    total_gen_g_loss = gen_g_loss + total_cycle_loss + identity_loss(real_y, same_y)\n",
    "    total_gen_f_loss = gen_f_loss + total_cycle_loss + identity_loss(real_x, same_x)\n",
    "\n",
    "    disc_x_loss = discriminator_loss(disc_real_x, disc_fake_x)\n",
    "    disc_y_loss = discriminator_loss(disc_real_y, disc_fake_y)\n",
    "  \n",
    "  # Calculate the gradients for generator and discriminator\n",
    "  generator_g_gradients = tape.gradient(total_gen_g_loss, \n",
    "                                        generator_g.trainable_variables)\n",
    "  generator_f_gradients = tape.gradient(total_gen_f_loss, \n",
    "                                        generator_f.trainable_variables)\n",
    "  \n",
    "  discriminator_x_gradients = tape.gradient(disc_x_loss, \n",
    "                                            discriminator_x.trainable_variables)\n",
    "  discriminator_y_gradients = tape.gradient(disc_y_loss, \n",
    "                                            discriminator_y.trainable_variables)\n",
    "  \n",
    "  # Apply the gradients to the optimizer\n",
    "  generator_g_optimizer.apply_gradients(zip(generator_g_gradients, \n",
    "                                            generator_g.trainable_variables))\n",
    "\n",
    "  generator_f_optimizer.apply_gradients(zip(generator_f_gradients, \n",
    "                                            generator_f.trainable_variables))\n",
    "  \n",
    "  discriminator_x_optimizer.apply_gradients(zip(discriminator_x_gradients,\n",
    "                                                discriminator_x.trainable_variables))\n",
    "  \n",
    "  discriminator_y_optimizer.apply_gradients(zip(discriminator_y_gradients,\n",
    "                                                discriminator_y.trainable_variables))"
   ]
  },
  {
   "cell_type": "code",
   "execution_count": 28,
   "metadata": {},
   "outputs": [
    {
     "name": "stdout",
     "output_type": "stream",
     "text": [
      "Unexpected exception formatting exception. Falling back to standard exception\n"
     ]
    },
    {
     "name": "stderr",
     "output_type": "stream",
     "text": [
      "Traceback (most recent call last):\n",
      "  File \"c:\\Users\\azhur\\AppData\\Local\\Programs\\Python\\Python310\\lib\\site-packages\\IPython\\core\\interactiveshell.py\", line 3398, in run_code\n",
      "    exec(code_obj, self.user_global_ns, self.user_ns)\n",
      "  File \"C:\\Users\\azhur\\AppData\\Local\\Temp\\ipykernel_28916\\1024147722.py\", line 2, in <cell line: 1>\n",
      "    start = time.time()\n",
      "NameError: name 'time' is not defined\n",
      "\n",
      "During handling of the above exception, another exception occurred:\n",
      "\n",
      "Traceback (most recent call last):\n",
      "  File \"c:\\Users\\azhur\\AppData\\Local\\Programs\\Python\\Python310\\lib\\site-packages\\IPython\\core\\interactiveshell.py\", line 1993, in showtraceback\n",
      "    stb = self.InteractiveTB.structured_traceback(\n",
      "  File \"c:\\Users\\azhur\\AppData\\Local\\Programs\\Python\\Python310\\lib\\site-packages\\IPython\\core\\ultratb.py\", line 1118, in structured_traceback\n",
      "    return FormattedTB.structured_traceback(\n",
      "  File \"c:\\Users\\azhur\\AppData\\Local\\Programs\\Python\\Python310\\lib\\site-packages\\IPython\\core\\ultratb.py\", line 1012, in structured_traceback\n",
      "    return VerboseTB.structured_traceback(\n",
      "  File \"c:\\Users\\azhur\\AppData\\Local\\Programs\\Python\\Python310\\lib\\site-packages\\IPython\\core\\ultratb.py\", line 865, in structured_traceback\n",
      "    formatted_exception = self.format_exception_as_a_whole(etype, evalue, etb, number_of_lines_of_context,\n",
      "  File \"c:\\Users\\azhur\\AppData\\Local\\Programs\\Python\\Python310\\lib\\site-packages\\IPython\\core\\ultratb.py\", line 799, in format_exception_as_a_whole\n",
      "    self.get_records(etb, number_of_lines_of_context, tb_offset) if etb else []\n",
      "  File \"c:\\Users\\azhur\\AppData\\Local\\Programs\\Python\\Python310\\lib\\site-packages\\IPython\\core\\ultratb.py\", line 845, in get_records\n",
      "    style = stack_data.style_with_executing_node(style, \"bg:ansiyellow\")\n",
      "  File \"c:\\Users\\azhur\\AppData\\Local\\Programs\\Python\\Python310\\lib\\site-packages\\stack_data\\core.py\", line 424, in style_with_executing_node\n",
      "    class NewStyle(style):\n",
      "  File \"c:\\Users\\azhur\\AppData\\Local\\Programs\\Python\\Python310\\lib\\site-packages\\pygments\\style.py\", line 91, in __new__\n",
      "    ndef[4] = colorformat(styledef[3:])\n",
      "  File \"c:\\Users\\azhur\\AppData\\Local\\Programs\\Python\\Python310\\lib\\site-packages\\pygments\\style.py\", line 58, in colorformat\n",
      "    assert False, \"wrong color format %r\" % text\n",
      "AssertionError: wrong color format 'ansiyellow'\n"
     ]
    }
   ],
   "source": [
    "for epoch in range(EPOCHS):\n",
    "  start = time.time()\n",
    "\n",
    "  n = 0\n",
    "  for image_x, image_y in tf.data.Dataset.zip((train_horses, train_zebras)):\n",
    "    train_step(image_x, image_y)\n",
    "    if n % 10 == 0:\n",
    "      print ('.', end='')\n",
    "    n+=1\n",
    "\n",
    "  clear_output(wait=True)\n",
    "  # Using a consistent image (sample_horse) so that the progress of the model\n",
    "  # is clearly visible.\n",
    "  generate_images(generator_g, sample_horse)\n",
    "\n",
    "  if (epoch + 1) % 5 == 0:\n",
    "    ckpt_save_path = ckpt_manager.save()\n",
    "    print ('Saving checkpoint for epoch {} at {}'.format(epoch+1,\n",
    "                                                         ckpt_save_path))\n",
    "\n",
    "  print ('Time taken for epoch {} is {} sec\\n'.format(epoch + 1,\n",
    "                                                      time.time()-start))"
   ]
  },
  {
   "cell_type": "code",
   "execution_count": 29,
   "metadata": {},
   "outputs": [
    {
     "name": "stdout",
     "output_type": "stream",
     "text": [
      "Unexpected exception formatting exception. Falling back to standard exception\n"
     ]
    },
    {
     "name": "stderr",
     "output_type": "stream",
     "text": [
      "Traceback (most recent call last):\n",
      "  File \"c:\\Users\\azhur\\AppData\\Local\\Programs\\Python\\Python310\\lib\\site-packages\\IPython\\core\\interactiveshell.py\", line 3398, in run_code\n",
      "    exec(code_obj, self.user_global_ns, self.user_ns)\n",
      "  File \"C:\\Users\\azhur\\AppData\\Local\\Temp\\ipykernel_28916\\1696255569.py\", line 2, in <cell line: 2>\n",
      "    for inp in test_horses.take(5):\n",
      "NameError: name 'test_horses' is not defined\n",
      "\n",
      "During handling of the above exception, another exception occurred:\n",
      "\n",
      "Traceback (most recent call last):\n",
      "  File \"c:\\Users\\azhur\\AppData\\Local\\Programs\\Python\\Python310\\lib\\site-packages\\IPython\\core\\interactiveshell.py\", line 1993, in showtraceback\n",
      "    stb = self.InteractiveTB.structured_traceback(\n",
      "  File \"c:\\Users\\azhur\\AppData\\Local\\Programs\\Python\\Python310\\lib\\site-packages\\IPython\\core\\ultratb.py\", line 1118, in structured_traceback\n",
      "    return FormattedTB.structured_traceback(\n",
      "  File \"c:\\Users\\azhur\\AppData\\Local\\Programs\\Python\\Python310\\lib\\site-packages\\IPython\\core\\ultratb.py\", line 1012, in structured_traceback\n",
      "    return VerboseTB.structured_traceback(\n",
      "  File \"c:\\Users\\azhur\\AppData\\Local\\Programs\\Python\\Python310\\lib\\site-packages\\IPython\\core\\ultratb.py\", line 865, in structured_traceback\n",
      "    formatted_exception = self.format_exception_as_a_whole(etype, evalue, etb, number_of_lines_of_context,\n",
      "  File \"c:\\Users\\azhur\\AppData\\Local\\Programs\\Python\\Python310\\lib\\site-packages\\IPython\\core\\ultratb.py\", line 799, in format_exception_as_a_whole\n",
      "    self.get_records(etb, number_of_lines_of_context, tb_offset) if etb else []\n",
      "  File \"c:\\Users\\azhur\\AppData\\Local\\Programs\\Python\\Python310\\lib\\site-packages\\IPython\\core\\ultratb.py\", line 845, in get_records\n",
      "    style = stack_data.style_with_executing_node(style, \"bg:ansiyellow\")\n",
      "  File \"c:\\Users\\azhur\\AppData\\Local\\Programs\\Python\\Python310\\lib\\site-packages\\stack_data\\core.py\", line 424, in style_with_executing_node\n",
      "    class NewStyle(style):\n",
      "  File \"c:\\Users\\azhur\\AppData\\Local\\Programs\\Python\\Python310\\lib\\site-packages\\pygments\\style.py\", line 91, in __new__\n",
      "    ndef[4] = colorformat(styledef[3:])\n",
      "  File \"c:\\Users\\azhur\\AppData\\Local\\Programs\\Python\\Python310\\lib\\site-packages\\pygments\\style.py\", line 58, in colorformat\n",
      "    assert False, \"wrong color format %r\" % text\n",
      "AssertionError: wrong color format 'ansiyellow'\n"
     ]
    }
   ],
   "source": [
    "# Run the trained model on the test dataset\n",
    "for inp in test_horses.take(5):\n",
    "  generate_images(generator_g, inp)"
   ]
  }
 ],
 "metadata": {
  "kernelspec": {
   "display_name": "Python 3",
   "language": "python",
   "name": "python3"
  },
  "language_info": {
   "codemirror_mode": {
    "name": "ipython",
    "version": 3
   },
   "file_extension": ".py",
   "mimetype": "text/x-python",
   "name": "python",
   "nbconvert_exporter": "python",
   "pygments_lexer": "ipython3",
   "version": "3.10.2 (tags/v3.10.2:a58ebcc, Jan 17 2022, 14:12:15) [MSC v.1929 64 bit (AMD64)]"
  },
  "orig_nbformat": 4,
  "vscode": {
   "interpreter": {
    "hash": "e0374bbc5b6e8830e1c7992d2b29930f5be5fce85401b20117ea791a8a6544f0"
   }
  }
 },
 "nbformat": 4,
 "nbformat_minor": 2
}
